[2024-09-19T18:13:44.683+0000] {taskinstance.py:1157} INFO - Dependencies all met for dep_context=non-requeueable deps ti=<TaskInstance: customer_dim_generator.generate_customer_dim_data scheduled__2024-09-15T00:00:00+00:00 [queued]>
[2024-09-19T18:13:46.673+0000] {taskinstance.py:1157} INFO - Dependencies all met for dep_context=requeueable deps ti=<TaskInstance: customer_dim_generator.generate_customer_dim_data scheduled__2024-09-15T00:00:00+00:00 [queued]>
[2024-09-19T18:13:46.938+0000] {taskinstance.py:1359} INFO - Starting attempt 1 of 1
[2024-09-19T18:13:50.438+0000] {taskinstance.py:1380} INFO - Executing <Task(PythonOperator): generate_customer_dim_data> on 2024-09-15 00:00:00+00:00
[2024-09-19T18:13:51.281+0000] {standard_task_runner.py:57} INFO - Started process 435 to run task
[2024-09-19T18:13:51.344+0000] {standard_task_runner.py:84} INFO - Running: ['***', 'tasks', 'run', 'customer_dim_generator', 'generate_customer_dim_data', 'scheduled__2024-09-15T00:00:00+00:00', '--job-id', '32', '--raw', '--subdir', 'DAGS_FOLDER/customer_dim_generator.py', '--cfg-path', '/tmp/tmpq3gghqko']
[2024-09-19T18:13:51.593+0000] {standard_task_runner.py:85} INFO - Job 32: Subtask generate_customer_dim_data
[2024-09-19T18:13:54.443+0000] {task_command.py:415} INFO - Running <TaskInstance: customer_dim_generator.generate_customer_dim_data scheduled__2024-09-15T00:00:00+00:00 [running]> on host 48913e9acee9
[2024-09-19T18:14:14.496+0000] {taskinstance.py:1935} ERROR - Task failed with exception
Traceback (most recent call last):
  File "/home/airflow/.local/lib/python3.8/site-packages/sqlalchemy/engine/base.py", line 1910, in _execute_context
    self.dialect.do_execute(
  File "/home/airflow/.local/lib/python3.8/site-packages/sqlalchemy/engine/default.py", line 736, in do_execute
    cursor.execute(statement, parameters)
psycopg2.errors.ForeignKeyViolation: insert or update on table "rendered_task_instance_fields" violates foreign key constraint "rtif_ti_fkey"
DETAIL:  Key (dag_id, task_id, run_id, map_index)=(customer_dim_generator, generate_customer_dim_data, scheduled__2024-09-15T00:00:00+00:00, -1) is not present in table "task_instance".


The above exception was the direct cause of the following exception:

Traceback (most recent call last):
  File "/home/airflow/.local/lib/python3.8/site-packages/airflow/models/taskinstance.py", line 1516, in _run_raw_task
    self._execute_task_with_callbacks(context, test_mode, session=session)
  File "/home/airflow/.local/lib/python3.8/site-packages/airflow/models/taskinstance.py", line 1649, in _execute_task_with_callbacks
    RenderedTaskInstanceFields.write(rtif)
  File "/home/airflow/.local/lib/python3.8/site-packages/airflow/utils/session.py", line 77, in wrapper
    return func(*args, session=session, **kwargs)
  File "/usr/local/lib/python3.8/contextlib.py", line 120, in __exit__
    next(self.gen)
  File "/home/airflow/.local/lib/python3.8/site-packages/airflow/utils/session.py", line 37, in create_session
    session.commit()
  File "/home/airflow/.local/lib/python3.8/site-packages/sqlalchemy/orm/session.py", line 1454, in commit
    self._transaction.commit(_to_root=self.future)
  File "/home/airflow/.local/lib/python3.8/site-packages/sqlalchemy/orm/session.py", line 832, in commit
    self._prepare_impl()
  File "/home/airflow/.local/lib/python3.8/site-packages/sqlalchemy/orm/session.py", line 811, in _prepare_impl
    self.session.flush()
  File "/home/airflow/.local/lib/python3.8/site-packages/sqlalchemy/orm/session.py", line 3449, in flush
    self._flush(objects)
  File "/home/airflow/.local/lib/python3.8/site-packages/sqlalchemy/orm/session.py", line 3589, in _flush
    transaction.rollback(_capture_exception=True)
  File "/home/airflow/.local/lib/python3.8/site-packages/sqlalchemy/util/langhelpers.py", line 70, in __exit__
    compat.raise_(
  File "/home/airflow/.local/lib/python3.8/site-packages/sqlalchemy/util/compat.py", line 211, in raise_
    raise exception
  File "/home/airflow/.local/lib/python3.8/site-packages/sqlalchemy/orm/session.py", line 3549, in _flush
    flush_context.execute()
  File "/home/airflow/.local/lib/python3.8/site-packages/sqlalchemy/orm/unitofwork.py", line 456, in execute
    rec.execute(self)
  File "/home/airflow/.local/lib/python3.8/site-packages/sqlalchemy/orm/unitofwork.py", line 630, in execute
    util.preloaded.orm_persistence.save_obj(
  File "/home/airflow/.local/lib/python3.8/site-packages/sqlalchemy/orm/persistence.py", line 245, in save_obj
    _emit_insert_statements(
  File "/home/airflow/.local/lib/python3.8/site-packages/sqlalchemy/orm/persistence.py", line 1097, in _emit_insert_statements
    c = connection._execute_20(
  File "/home/airflow/.local/lib/python3.8/site-packages/sqlalchemy/engine/base.py", line 1710, in _execute_20
    return meth(self, args_10style, kwargs_10style, execution_options)
  File "/home/airflow/.local/lib/python3.8/site-packages/sqlalchemy/sql/elements.py", line 334, in _execute_on_connection
    return connection._execute_clauseelement(
  File "/home/airflow/.local/lib/python3.8/site-packages/sqlalchemy/engine/base.py", line 1577, in _execute_clauseelement
    ret = self._execute_context(
  File "/home/airflow/.local/lib/python3.8/site-packages/sqlalchemy/engine/base.py", line 1953, in _execute_context
    self._handle_dbapi_exception(
  File "/home/airflow/.local/lib/python3.8/site-packages/sqlalchemy/engine/base.py", line 2134, in _handle_dbapi_exception
    util.raise_(
  File "/home/airflow/.local/lib/python3.8/site-packages/sqlalchemy/util/compat.py", line 211, in raise_
    raise exception
  File "/home/airflow/.local/lib/python3.8/site-packages/sqlalchemy/engine/base.py", line 1910, in _execute_context
    self.dialect.do_execute(
  File "/home/airflow/.local/lib/python3.8/site-packages/sqlalchemy/engine/default.py", line 736, in do_execute
    cursor.execute(statement, parameters)
sqlalchemy.exc.IntegrityError: (psycopg2.errors.ForeignKeyViolation) insert or update on table "rendered_task_instance_fields" violates foreign key constraint "rtif_ti_fkey"
DETAIL:  Key (dag_id, task_id, run_id, map_index)=(customer_dim_generator, generate_customer_dim_data, scheduled__2024-09-15T00:00:00+00:00, -1) is not present in table "task_instance".

[SQL: INSERT INTO rendered_task_instance_fields (dag_id, task_id, run_id, map_index, rendered_fields, k8s_pod_yaml) VALUES (%(dag_id)s, %(task_id)s, %(run_id)s, %(map_index)s, %(rendered_fields)s, %(k8s_pod_yaml)s)]
[parameters: {'dag_id': 'customer_dim_generator', 'task_id': 'generate_customer_dim_data', 'run_id': 'scheduled__2024-09-15T00:00:00+00:00', 'map_index': -1, 'rendered_fields': '{"templates_dict": null, "op_args": [], "op_kwargs": {}}', 'k8s_pod_yaml': 'null'}]
(Background on this error at: https://sqlalche.me/e/14/gkpj)
[2024-09-19T18:14:22.484+0000] {taskinstance.py:1398} INFO - Marking task as FAILED. dag_id=customer_dim_generator, task_id=generate_customer_dim_data, execution_date=20240915T000000, start_date=20240919T181344, end_date=20240919T181422
[2024-09-19T18:14:26.604+0000] {standard_task_runner.py:104} ERROR - Failed to execute job 32 for task generate_customer_dim_data ((psycopg2.errors.ForeignKeyViolation) insert or update on table "task_fail" violates foreign key constraint "task_fail_ti_fkey"
DETAIL:  Key (dag_id, task_id, run_id, map_index)=(customer_dim_generator, generate_customer_dim_data, scheduled__2024-09-15T00:00:00+00:00, -1) is not present in table "task_instance".

[SQL: INSERT INTO task_fail (task_id, dag_id, run_id, map_index, start_date, end_date, duration) VALUES (%(task_id)s, %(dag_id)s, %(run_id)s, %(map_index)s, %(start_date)s, %(end_date)s, %(duration)s) RETURNING task_fail.id]
[parameters: {'task_id': 'generate_customer_dim_data', 'dag_id': 'customer_dim_generator', 'run_id': 'scheduled__2024-09-15T00:00:00+00:00', 'map_index': -1, 'start_date': datetime.datetime(2024, 9, 19, 18, 13, 44, 953455, tzinfo=Timezone('UTC')), 'end_date': datetime.datetime(2024, 9, 19, 18, 14, 22, 450914, tzinfo=Timezone('UTC')), 'duration': 37}]
(Background on this error at: https://sqlalche.me/e/14/gkpj); 435)
[2024-09-19T18:14:28.981+0000] {local_task_job_runner.py:228} INFO - Task exited with return code 1
[2024-09-19T18:23:34.993+0000] {taskinstance.py:1157} INFO - Dependencies all met for dep_context=non-requeueable deps ti=<TaskInstance: customer_dim_generator.generate_customer_dim_data scheduled__2024-09-15T00:00:00+00:00 [queued]>
[2024-09-19T18:23:35.137+0000] {taskinstance.py:1157} INFO - Dependencies all met for dep_context=requeueable deps ti=<TaskInstance: customer_dim_generator.generate_customer_dim_data scheduled__2024-09-15T00:00:00+00:00 [queued]>
[2024-09-19T18:23:35.139+0000] {taskinstance.py:1359} INFO - Starting attempt 1 of 1
[2024-09-19T18:23:35.212+0000] {taskinstance.py:1380} INFO - Executing <Task(PythonOperator): generate_customer_dim_data> on 2024-09-15 00:00:00+00:00
[2024-09-19T18:23:35.251+0000] {standard_task_runner.py:57} INFO - Started process 220 to run task
[2024-09-19T18:23:35.275+0000] {standard_task_runner.py:84} INFO - Running: ['***', 'tasks', 'run', 'customer_dim_generator', 'generate_customer_dim_data', 'scheduled__2024-09-15T00:00:00+00:00', '--job-id', '46', '--raw', '--subdir', 'DAGS_FOLDER/customer_dim_generator.py', '--cfg-path', '/tmp/tmp7_9ky7o1']
[2024-09-19T18:23:35.309+0000] {standard_task_runner.py:85} INFO - Job 46: Subtask generate_customer_dim_data
[2024-09-19T18:23:35.782+0000] {task_command.py:415} INFO - Running <TaskInstance: customer_dim_generator.generate_customer_dim_data scheduled__2024-09-15T00:00:00+00:00 [running]> on host 48913e9acee9
[2024-09-19T18:23:36.146+0000] {taskinstance.py:1660} INFO - Exporting env vars: AIRFLOW_CTX_DAG_OWNER='codewithyu' AIRFLOW_CTX_DAG_ID='customer_dim_generator' AIRFLOW_CTX_TASK_ID='generate_customer_dim_data' AIRFLOW_CTX_EXECUTION_DATE='2024-09-15T00:00:00+00:00' AIRFLOW_CTX_TRY_NUMBER='1' AIRFLOW_CTX_DAG_RUN_ID='scheduled__2024-09-15T00:00:00+00:00'
[2024-09-19T18:23:36.195+0000] {logging_mixin.py:151} INFO - CSV file './customer_dim_large_data.csv' with 100 rows has been generated successfully.
[2024-09-19T18:23:36.198+0000] {python.py:194} INFO - Done. Returned value was: None
[2024-09-19T18:23:36.222+0000] {taskinstance.py:1398} INFO - Marking task as SUCCESS. dag_id=customer_dim_generator, task_id=generate_customer_dim_data, execution_date=20240915T000000, start_date=20240919T182335, end_date=20240919T182336
[2024-09-19T18:23:36.287+0000] {local_task_job_runner.py:228} INFO - Task exited with return code 0
[2024-09-19T18:23:36.359+0000] {taskinstance.py:2776} INFO - 0 downstream tasks scheduled from follow-on schedule check
